Workbook

Sheet Дашборд
A1: БИТВА ПРИ КРИВОМ ЗЕРКАЛЕ · The Brass Spyglass
A2: Производственный трекер · 1 Billion AI Film Award 2027 (1 Billion Followers Summit × BytePlus Seedance)
A4: Ключевые цифры | B4: Значение | C4: Цель | D4: Проверка
A5: Официальный дедлайн (Дубай, UTC+4) | B5: 46346.999 | C5: 22:59 МСК
A6: Наш внутренний срок подачи | B6: 46344 | C6: запас 2 дня
A7: Дней до внутреннего срока | B7: =B6-TODAY() -> 19 | D7: =IF(B7<0,"⚠ ПРОСРОЧЕНО",IF(B7<=3,"⚠ Финиш","✓ OK")) -> ✓ OK
A8: Хронометраж по плану сцен, сек | B8: =SUM(Сцены!$E$2:$E$13) -> 360 | C8: 300–420 | D8: =IF(AND(B8>=300,B8<=420),"✓ OK","⚠ Вне 5–7 мин") -> ✓ OK
A9: то же в мм:сс | B9: =B8/86400 -> 0.0041666667 | C9: 5:00–7:00
A10: Хронометраж по шотам (без вырезанных), сек | B10: =SUMIFS(Шоты!$F$2:$F$500,Шоты!$M$2:$M$500,"<>Вырезано") -> 360 | C10: 300–420 | D10: =IF(AND(B10>=300,B10<=420),"✓ OK","⚠ Вне 5–7 мин") -> ✓ OK
A11: Доля Seedance по шотам | B11: =IFERROR(SUMIFS(Шоты!$F$2:$F$500,Шоты!$I$2:$I$500,"Seedance",Шоты!$M$2:$M$500,"<>Вырезано")/B10,0) -> 1 | C11: ≥ 70% | D11: =IF(B11>=0.7,"✓ OK","⚠ Меньше 70%") -> ✓ OK
A12: Готово секунд фильма | B12: =SUMIFS(Шоты!$F$2:$F$500,Шоты!$M$2:$M$500,"Готово") -> 0 | D12: =IFERROR(B12/B10,0) -> 0
A13: Просроченных пунктов (все листы) | B13: =COUNTIFS(Сцены!$V$2:$V$500,"<"&TODAY(),Сцены!$S$2:$S$500,"<>Готово",Сцены!$S$2:$S$500,"<>Вырезано")+COUNTIFS(Шоты!$P$2:$P$500,"<"&TODAY(),Шоты!$M$2:$M$500,"<>Готово",Шоты!$M$2:$M$500,"<>Вырезано")+COUNTIFS(Ассеты!$L$2:$L$500,"<"&TODAY(),Ассеты!$I$2:$I$500,"<>Готово",Ассеты!$I$2:$I$500,"<>Вырезано")+COUNTIFS(Задачи!$E$2:$E$500,"<"&TODAY(),Задачи!$G$2:$G$500,"<>Готово",Задачи!$G$2:$G$500,"<>Вырезано") -> 0 | C13: 0 | D13: =IF(B13=0,"✓ OK","⚠ Есть просрочка") -> ✓ OK
A14: Ассетов, которых нет ни в одном шоте | B14: =COUNTIF(Ассеты!$G$2:$G$150,0) -> 1 | C14: 0 | D14: =IF(B14=0,"✓ OK","⚠ Проверить") -> ⚠ Проверить
A15: Сцен, где шоты расходятся с планом > 2 сек | B15: =COUNTIF(Сцены!$P$2:$P$13,">2")+COUNTIF(Сцены!$P$2:$P$13,"<-2") -> 0 | C15: 0 | D15: =IF(B15=0,"✓ OK","⚠ Проверить") -> ✓ OK
A16: Шотов длиннее 15 сек (лимит клипа Seedance) | B16: =COUNTIF(Шоты!$F$2:$F$500,">15") -> 0 | C16: 0 | D16: =IF(B16=0,"✓ OK","⚠ Резать на склейки") -> ✓ OK
A18: Прогресс по листам
A19: Лист | B19: Всего | C19: Не начато | D19: В работе | E19: На проверке | F19: Доработать | G19: Готово | H19: Вырезано | I19: % готово
A20: Сцены | B20: =COUNTIF(Сцены!$S$2:$S$500,"?*") -> 12 | C20: =COUNTIF(Сцены!$S$2:$S$500,C$19) -> 12 | D20: =COUNTIF(Сцены!$S$2:$S$500,D$19) -> 0 | E20: =COUNTIF(Сцены!$S$2:$S$500,E$19) -> 0 | F20: =COUNTIF(Сцены!$S$2:$S$500,F$19) -> 0 | G20: =COUNTIF(Сцены!$S$2:$S$500,G$19) -> 0 | H20: =COUNTIF(Сцены!$S$2:$S$500,H$19) -> 0 | I20: =IFERROR(G20/(B20-H20),0) -> 0
A21: Шоты | B21: =COUNTIF(Шоты!$M$2:$M$500,"?*") -> 69 | C21: =COUNTIF(Шоты!$M$2:$M$500,C$19) -> 69 | D21: =COUNTIF(Шоты!$M$2:$M$500,D$19) -> 0 | E21: =COUNTIF(Шоты!$M$2:$M$500,E$19) -> 0 | F21: =COUNTIF(Шоты!$M$2:$M$500,F$19) -> 0 | G21: =COUNTIF(Шоты!$M$2:$M$500,G$19) -> 0 | H21: =COUNTIF(Шоты!$M$2:$M$500,H$19) -> 0 | I21: =IFERROR(G21/(B21-H21),0) -> 0
A22: Ассеты | B22: =COUNTIF(Ассеты!$I$2:$I$500,"?*") -> 54 | C22: =COUNTIF(Ассеты!$I$2:$I$500,C$19) -> 54 | D22: =COUNTIF(Ассеты!$I$2:$I$500,D$19) -> 0 | E22: =COUNTIF(Ассеты!$I$2:$I$500,E$19) -> 0 | F22: =COUNTIF(Ассеты!$I$2:$I$500,F$19) -> 0 | G22: =COUNTIF(Ассеты!$I$2:$I$500,G$19) -> 0 | H22: =COUNTIF(Ассеты!$I$2:$I$500,H$19) -> 0 | I22: =IFERROR(G22/(B22-H22),0) -> 0
A23: Сетапы | B23: =COUNTIF(Сетапы!$G$2:$G$500,"?*") -> 13 | C23: =COUNTIF(Сетапы!$G$2:$G$500,C$19) -> 13 | D23: =COUNTIF(Сетапы!$G$2:$G$500,D$19) -> 0 | E23: =COUNTIF(Сетапы!$G$2:$G$500,E$19) -> 0 | F23: =COUNTIF(Сетапы!$G$2:$G$500,F$19) -> 0 | G23: =COUNTIF(Сетапы!$G$2:$G$500,G$19) -> 0 | H23: =COUNTIF(Сетапы!$G$2:$G$500,H$19) -> 0 | I23: =IFERROR(G23/(B23-H23),0) -> 0
A24: Звук | B24: =COUNTIF(Звук!$I$2:$I$500,"?*") -> 23 | C24: =COUNTIF(Звук!$I$2:$I$500,C$19) -> 23 | D24: =COUNTIF(Звук!$I$2:$I$500,D$19) -> 0 | E24: =COUNTIF(Звук!$I$2:$I$500,E$19) -> 0 | F24: =COUNTIF(Звук!$I$2:$I$500,F$19) -> 0 | G24: =COUNTIF(Звук!$I$2:$I$500,G$19) -> 0 | H24: =COUNTIF(Звук!$I$2:$I$500,H$19) -> 0 | I24: =IFERROR(G24/(B24-H24),0) -> 0
A25: Задачи | B25: =COUNTIF(Задачи!$G$2:$G$500,"?*") -> 29 | C25: =COUNTIF(Задачи!$G$2:$G$500,C$19) -> 28 | D25: =COUNTIF(Задачи!$G$2:$G$500,D$19) -> 0 | E25: =COUNTIF(Задачи!$G$2:$G$500,E$19) -> 0 | F25: =COUNTIF(Задачи!$G$2:$G$500,F$19) -> 0 | G25: =COUNTIF(Задачи!$G$2:$G$500,G$19) -> 1 | H25: =COUNTIF(Задачи!$G$2:$G$500,H$19) -> 0 | I25: =IFERROR(G25/(B25-H25),0) -> 0.034482759
A28: Шоты по этапам
A29: Этап | B29: Шотов | C29: Секунд
A30: Раскадровка | B30: =COUNTIFS(Шоты!$J$2:$J$500,A30,Шоты!$M$2:$M$500,"<>Вырезано") -> 69 | C30: =SUMIFS(Шоты!$F$2:$F$500,Шоты!$J$2:$J$500,A30,Шоты!$M$2:$M$500,"<>Вырезано") -> 360
A31: Блокаут | B31: =COUNTIFS(Шоты!$J$2:$J$500,A31,Шоты!$M$2:$M$500,"<>Вырезано") -> 0 | C31: =SUMIFS(Шоты!$F$2:$F$500,Шоты!$J$2:$J$500,A31,Шоты!$M$2:$M$500,"<>Вырезано") -> 0
A32: Промпт | B32: =COUNTIFS(Шоты!$J$2:$J$500,A32,Шоты!$M$2:$M$500,"<>Вырезано") -> 0 | C32: =SUMIFS(Шоты!$F$2:$F$500,Шоты!$J$2:$J$500,A32,Шоты!$M$2:$M$500,"<>Вырезано") -> 0
A33: Генерация | B33: =COUNTIFS(Шоты!$J$2:$J$500,A33,Шоты!$M$2:$M$500,"<>Вырезано") -> 0 | C33: =SUMIFS(Шоты!$F$2:$F$500,Шоты!$J$2:$J$500,A33,Шоты!$M$2:$M$500,"<>Вырезано") -> 0
A34: Отбор дубля | B34: =COUNTIFS(Шоты!$J$2:$J$500,A34,Шоты!$M$2:$M$500,"<>Вырезано") -> 0 | C34: =SUMIFS(Шоты!$F$2:$F$500,Шоты!$J$2:$J$500,A34,Шоты!$M$2:$M$500,"<>Вырезано") -> 0
A35: В монтаже | B35: =COUNTIFS(Шоты!$J$2:$J$500,A35,Шоты!$M$2:$M$500,"<>Вырезано") -> 0 | C35: =SUMIFS(Шоты!$F$2:$F$500,Шоты!$J$2:$J$500,A35,Шоты!$M$2:$M$500,"<>Вырезано") -> 0
A36: Финал | B36: =COUNTIFS(Шоты!$J$2:$J$500,A36,Шоты!$M$2:$M$500,"<>Вырезано") -> 0 | C36: =SUMIFS(Шоты!$F$2:$F$500,Шоты!$J$2:$J$500,A36,Шоты!$M$2:$M$500,"<>Вырезано") -> 0
A39: Требования конкурса (сверено 30.10.2026)
A40: • Хронометраж 5–7 минут, одна законченная история, сделанная специально для конкурса
A41: • 16:9, 1080p, MOV или MP4; интро-карточка организатора идёт перед фильмом
A42: • Seedance — основной инструмент и генерирует не меньше 70% готового фильма
A43: • Английские субтитры обязательны, даже если речь на английском
A44: • Ссылка на фильм — приватная или unlisted
A45: • Тема — одна из пяти: Society & Humanitarian · Truth, Fake News & Misinformation · Humans & AI · Climate & Nature · Human Relationships
A46: • Оценка: AI Integration 30 · Storytelling 30 · Creativity & Aesthetic 20 · Technical Execution 20
...

Sheet Сцены
A1: № | B1: Сцена | C1: Локация | D1: Время суток | E1: План, сек | F1: Начало | G1: Конец | H1: Персонажи | I1: Ключевые ассеты | J1: Реплики (EN) | K1: Барабан 0–5 | L1: Смысл сцены | M1: Если сокращать | N1: Шотов | O1: Сумма шотов, сек | P1: Δ шоты − план | Q1: Готово шотов | R1: % готовности | S1: Статус | T1: Приоритет | U1: Ответственный | V1: Дедлайн | W1: Комментарий
A2: 1 | B2: Два зеркала | C2: Пролив, обе стены | D2: Утро | E2: 25 | F2: =0 -> 0 | G2: =F2+E2/86400 -> 0.00028935185 | H2: Оба дозорных | I2: Кривые трубы, оба острова, силуэт третьего острова | J2: — (ветер, чайки, скрип труб) | K2: 0 | L2: Главная шутка: труба искажает. Оба берега бедные. | M2: Не трогать: здесь сетап третьего острова | N2: =COUNTIF(Шоты!$B$2:$B$500,A2) -> 6 | O2: =SUMIFS(Шоты!$F$2:$F$500,Шоты!$B$2:$B$500,A2,Шоты!$M$2:$M$500,"<>Вырезано") -> 25 | P2: =O2-E2 -> 0 | Q2: =COUNTIFS(Шоты!$B$2:$B$500,A2,Шоты!$M$2:$M$500,"Готово") -> 0 | R2: =IFERROR(Q2/(N2-COUNTIFS(Шоты!$B$2:$B$500,A2,Шоты!$M$2:$M$500,"Вырезано")),0) -> 0 | S2: Не начато | T2: Высокий
A3: 2 | B3: Блеф как политика | C3: Дворцы Севера и Юга | D3: День | E3: 30 | F3: =G2 -> 0.00028935185 | G3: =F3+E3/86400 -> 0.00063657407 | H3: Оба правителя, слуги | I3: Трубы правителей, золотая ткань, медный купол | J3: We are poor. But they? Look how they shine! | K3: 0 | L3: Каждый уверен, что блефует только он. Мотор фильма. | M3: До 4 мин: склеить со сц. 3 | N3: =COUNTIF(Шоты!$B$2:$B$500,A3) -> 6 | O3: =SUMIFS(Шоты!$F$2:$F$500,Шоты!$B$2:$B$500,A3,Шоты!$M$2:$M$500,"<>Вырезано") -> 30 | P3: =O3-E3 -> 0 | Q3: =COUNTIFS(Шоты!$B$2:$B$500,A3,Шоты!$M$2:$M$500,"Готово") -> 0 | R3: =IFERROR(Q3/(N3-COUNTIFS(Шоты!$B$2:$B$500,A3,Шоты!$M$2:$M$500,"Вырезано")),0) -> 0 | S3: Не начато | T3: Средний
A4: 3 | B4: Овца | C4: Мастерская красильщика (Север) | D4: Рассвет | E4: 25 | F4: =G3 -> 0.00063657407 | G4: =F4+E4/86400 -> 0.00092592593 | H4: Красильщик | I4: Овца, чан с оранжевой водной краской | J4: — | K4: 0 | L4: Рождение «тигра». Краска водная (сетап к сц. 11). | M4: До 4 мин: склеить со сц. 2 | N4: =COUNTIF(Шоты!$B$2:$B$500,A4) -> 5 | O4: =SUMIFS(Шоты!$F$2:$F$500,Шоты!$B$2:$B$500,A4,Шоты!$M$2:$M$500,"<>Вырезано") -> 25 | P4: =O4-E4 -> 0 | Q4: =COUNTIFS(Шоты!$B$2:$B$500,A4,Шоты!$M$2:$M$500,"Готово") -> 0 | R4: =IFERROR(Q4/(N4-COUNTIFS(Шоты!$B$2:$B$500,A4,Шоты!$M$2:$M$500,"Вырезано")),0) -> 0 | S4: Не начато | T4: Средний
A5: 4 | B5: Тигр | C5: Южная стена → улицы → дворец Юга | D5: Утро | E5: 30 | F5: =G4 -> 0.00092592593 | G5: =F5+E5/86400 -> 0.0012731481 | H5: Дозорный Юга, правитель Юга | I5: Кривая труба, полосатая овца | J5: Ma lord, ma lord! The North has TIGERS! / Many. Angry. One with a tail. / We have no tigers. | K5: 1 | L5: Дозорный накидывает подробности, никто не проверяет. | M5: До 3 мин: сц. 1–4 одним блоком «тигр» | N5: =COUNTIF(Шоты!$B$2:$B$500,A5) -> 6 | O5: =SUMIFS(Шоты!$F$2:$F$500,Шоты!$B$2:$B$500,A5,Шоты!$M$2:$M$500,"<>Вырезано") -> 30 | P5: =O5-E5 -> 0 | Q5: =COUNTIFS(Шоты!$B$2:$B$500,A5,Шоты!$M$2:$M$500,"Готово") -> 0 | R5: =IFERROR(Q5/(N5-COUNTIFS(Шоты!$B$2:$B$500,A5,Шоты!$M$2:$M$500,"Вырезано")),0) -> 0 | S5: Не начато | T5: Высокий
A6: 5 | B6: Юг отвечает: слон | C6: Двор дворца Юга, набережная | D6: Ночь → утро | E6: 30 | F6: =G5 -> 0.0012731481 | G6: =F6+E6/86400 -> 0.0016203704 | H6: Правитель Юга, ремесленники | I6: «Бронированный слон» (3 осла, ковёр, печные трубы) | J6: Terror. But affordable. | K6: 2 | L6: Первый ответный фейк. | M6: До 4 мин: склеить со сц. 6 | N6: =COUNTIF(Шоты!$B$2:$B$500,A6) -> 5 | O6: =SUMIFS(Шоты!$F$2:$F$500,Шоты!$B$2:$B$500,A6,Шоты!$M$2:$M$500,"<>Вырезано") -> 30 | P6: =O6-E6 -> 0 | Q6: =COUNTIFS(Шоты!$B$2:$B$500,A6,Шоты!$M$2:$M$500,"Готово") -> 0 | R6: =IFERROR(Q6/(N6-COUNTIFS(Шоты!$B$2:$B$500,A6,Шоты!$M$2:$M$500,"Вырезано")),0) -> 0 | S6: Не начато | T6: Средний
A7: 6 | B7: Север отвечает | C7: Таверна, крыши, кузница (Север) | D7: День → вечер | E7: 30 | F7: =G6 -> 0.0016203704 | G7: =F7+E7/86400 -> 0.0019675926 | H7: Дозорный Севера, правитель Севера, слушатели, кузнецы | I7: Тазы-щиты, чёрный дым | J7: A hundred elephants. They breathe fire. / A thousand soldiers. By morning. | K7: 2 | L7: Эскалация: подробностей больше, ответ дороже. | M7: До 4 мин: склеить со сц. 5 | N7: =COUNTIF(Шоты!$B$2:$B$500,A7) -> 6 | O7: =SUMIFS(Шоты!$F$2:$F$500,Шоты!$B$2:$B$500,A7,Шоты!$M$2:$M$500,"<>Вырезано") -> 30 | P7: =O7-E7 -> 0 | Q7: =COUNTIFS(Шоты!$B$2:$B$500,A7,Шоты!$M$2:$M$500,"Готово") -> 0 | R7: =IFERROR(Q7/(N7-COUNTIFS(Шоты!$B$2:$B$500,A7,Шоты!$M$2:$M$500,"Вырезано")),0) -> 0 | S7: Не начато | T7: Средний
A8: 7 | B8: Гонка бутафории (монтаж) | C8: Обе стороны | D8: День | E8: 40 | F8: =G7 -> 0.0019675926 | G8: =F8+E8/86400 -> 0.0024305556 | H8: Ремесленники, оба правителя | I8: Великаны на ходулях, чучела, брёвна-пушки, бочки, овцы-тигры, ослы в кастрюлях | J8: — | K8: 5 | L8: Каждая выдумка нелепее. Барабаны нарастают. | M8: До 4 мин: две пары вместо трёх | N8: =COUNTIF(Шоты!$B$2:$B$500,A8) -> 6 | O8: =SUMIFS(Шоты!$F$2:$F$500,Шоты!$B$2:$B$500,A8,Шоты!$M$2:$M$500,"<>Вырезано") -> 40 | P8: =O8-E8 -> 0 | Q8: =COUNTIFS(Шоты!$B$2:$B$500,A8,Шоты!$M$2:$M$500,"Готово") -> 0 | R8: =IFERROR(Q8/(N8-COUNTIFS(Шоты!$B$2:$B$500,A8,Шоты!$M$2:$M$500,"Вырезано")),0) -> 0 | S8: Не начато | T8: Средний
A9: 8 | B9: Смех становится страхом | C9: Стены и переулки | D9: Сумерки | E9: 30 | F9: =G8 -> 0.0024305556 | G9: =F9+E9/86400 -> 0.0027777778 | H9: Жители, мальчишки-бегуны, барабанщик | I9: Трубы, картонные мечи | J9: Attack at dawn! | K9: 3 | L9: Фейк работает против своих создателей. | M9: До 4 мин: склеить со сц. 9 | N9: =COUNTIF(Шоты!$B$2:$B$500,A9) -> 6 | O9: =SUMIFS(Шоты!$F$2:$F$500,Шоты!$B$2:$B$500,A9,Шоты!$M$2:$M$500,"<>Вырезано") -> 30 | P9: =O9-E9 -> 0 | Q9: =COUNTIFS(Шоты!$B$2:$B$500,A9,Шоты!$M$2:$M$500,"Готово") -> 0 | R9: =IFERROR(Q9/(N9-COUNTIFS(Шоты!$B$2:$B$500,A9,Шоты!$M$2:$M$500,"Вырезано")),0) -> 0 | S9: Не начато | T9: Средний
A10: 9 | B10: Решение правителей | C10: Дворцы | D10: Вечер | E10: 30 | F10: =G9 -> 0.0027777778 | G10: =F10+E10/86400 -> 0.003125 | H10: Оба правителя | I10: Бутафория, туман над проливом | J10: In the fog, a donkey is a dragon. | K10: 3 | L10: Ставка на туман. Встречу флотилий никто не предвидит. | M10: До 4 мин: склеить со сц. 8 | N10: =COUNTIF(Шоты!$B$2:$B$500,A10) -> 5 | O10: =SUMIFS(Шоты!$F$2:$F$500,Шоты!$B$2:$B$500,A10,Шоты!$M$2:$M$500,"<>Вырезано") -> 30 | P10: =O10-E10 -> 0 | Q10: =COUNTIFS(Шоты!$B$2:$B$500,A10,Шоты!$M$2:$M$500,"Готово") -> 0 | R10: =IFERROR(Q10/(N10-COUNTIFS(Шоты!$B$2:$B$500,A10,Шоты!$M$2:$M$500,"Вырезано")),0) -> 0 | S10: Не начато | T10: Средний
A11: 10 | B11: Ночь, туман | C11: Пролив | D11: Ночь | E11: 30 | F11: =G10 -> 0.003125 | G11: =F11+E11/86400 -> 0.0034722222 | H11: Флотилии, старики и мальчишки, дозорные | I11: Обе флотилии, чучела, овцы-тигры, тазы, туман | J11: — (блеяние) | K11: 4 | L11: Саспенс. Юмор только в деталях. | M11: До 4 мин: склеить со сц. 11 | N11: =COUNTIF(Шоты!$B$2:$B$500,A11) -> 6 | O11: =SUMIFS(Шоты!$F$2:$F$500,Шоты!$B$2:$B$500,A11,Шоты!$M$2:$M$500,"<>Вырезано") -> 30 | P11: =O11-E11 -> 0 | Q11: =COUNTIFS(Шоты!$B$2:$B$500,A11,Шоты!$M$2:$M$500,"Готово") -> 0 | R11: =IFERROR(Q11/(N11-COUNTIFS(Шоты!$B$2:$B$500,A11,Шоты!$M$2:$M$500,"Вырезано")),0) -> 0 | S11: Не начато | T11: Средний
A12: 11 | B12: Кривое зеркало | C12: Пролив | D12: Рассвет | E12: 40 | F12: =G11 -> 0.0034722222 | G12: =F12+E12/86400 -> 0.0039351852 | H12: Все, мальчишка-барабанщик | I12: Слон (распад), смытая овца, тазы, деревянные мечи | J12: — (10 сек тишины, смех) | K12: 5 | L12: Момент истины. Буквальное зеркало страха и тщеславия. | M12: Не сокращать паузу в 10 сек | N12: =COUNTIF(Шоты!$B$2:$B$500,A12) -> 7 | O12: =SUMIFS(Шоты!$F$2:$F$500,Шоты!$B$2:$B$500,A12,Шоты!$M$2:$M$500,"<>Вырезано") -> 40 | P12: =O12-E12 -> 0 | Q12: =COUNTIFS(Шоты!$B$2:$B$500,A12,Шоты!$M$2:$M$500,"Готово") -> 0 | R12: =IFERROR(Q12/(N12-COUNTIFS(Шоты!$B$2:$B$500,A12,Шоты!$M$2:$M$500,"Вырезано")),0) -> 0 | S12: Не начато | T12: Высокий
A13: 12 | B13: Мост из лодок и кода | C13: Пролив, плавучий базар | D13: Утро | E13: 20 | F13: =G12 -> 0.0039351852 | G13: =F13+E13/86400 -> 0.0041666667 | H13: Все, оба дозорных | I13: Лодки, еда, кривая труба, третий остров | J13: Ma lord?! | K13: 0 | L13: Никто ничему не научился, всё заново. | M13: Кода сокращается до кадра с трубой | N13: =COUNTIF(Шоты!$B$2:$B$500,A13) -> 5 | O13: =SUMIFS(Шоты!$F$2:$F$500,Шоты!$B$2:$B$500,A13,Шоты!$M$2:$M$500,"<>Вырезано") -> 20 | P13: =O13-E13 -> 0 | Q13: =COUNTIFS(Шоты!$B$2:$B$500,A13,Шоты!$M$2:$M$500,"Готово") -> 0 | R13: =IFERROR(Q13/(N13-COUNTIFS(Шоты!$B$2:$B$500,A13,Шоты!$M$2:$M$500,"Вырезано")),0) -> 0 | S13: Не начато | T13: Высокий
D15: ИТОГО | E15: =SUM(E2:E13) -> 360 | G15: =E15/86400 -> 0.0041666667 | N15: =SUM(N2:N13) -> 69 | O15: =SUM(O2:O13) -> 360

Sheet Шоты
A1: ID | B1: Сцена | C1: Описание кадра | D1: Крупность | E1: Камера / движение | F1: Длит., сек | G1: Ассеты в кадре (ID) | H1: Реплика / звук | I1: Инструмент | J1: Этап | K1: Дублей | L1: Выбранный дубль / файл | M1: Статус | N1: Приоритет | O1: Ответственный | P1: Дедлайн | Q1: Комментарий
A2: 01.01 | B2: 1 | C2: Симметричный общий: два острова, пролив, на каждом стена-крепость | D2: Общий | E2: Статика / медленный наезд | F2: 6 | G2: LC-01, LC-02, LC-03 | H2: Ветер, чайки | I2: Seedance | J2: Раскадровка | M2: Не начато | N2: Высокий
A3: 01.02 | B3: 1 | C3: Дозорный Севера на стене поднимает огромную медную трубу | D3: Средний | E3: Статика | F3: 3 | G3: CH-01, PR-01, LC-02 | H3: Скрип трубы | I3: Seedance | J3: Раскадровка | M3: Не начато | N3: Высокий
A4: 01.03 | B4: 1 | C4: Дозорный Юга зеркально поднимает свою трубу | D4: Средний | E4: Статика, зеркально 1.2 | F4: 3 | G4: CH-02, PR-01, LC-03 | H4: Скрип трубы | I4: Seedance | J4: Раскадровка | M4: Не начато | N4: Высокий
A5: 01.04 | B5: 1 | C5: Через трубу: золотые купола, знамёна, богатый город | D5: POV трубы | E5: Плавный проход | F5: 4 | G5: ST-01, LC-02 | I5: Seedance | J5: Раскадровка | M5: Не начато | N5: Высокий
A6: 01.05 | B6: 1 | C6: Без трубы: заплатки на крышах, облупленная штукатурка, бельё | D6: Общий | E6: Тот же ракурс, что 1.4 | F6: 4 | G6: LC-02, PR-16 | I6: Seedance | J6: Раскадровка | M6: Не начато | N6: Высокий
A7: 01.06 | B7: 1 | C7: Дозорные смотрят друг на друга; на краю горизонта мелькает силуэт третьего острова | D7: Общий | E7: Статика | F7: 5 | G7: CH-01, CH-02, LC-14 | I7: Seedance | J7: Раскадровка | M7: Не начато | N7: Высокий
A8: 02.01 | B8: 2 | C8: Правитель Севера смотрит в трубу на соседа и вздыхает | D8: Средний | E8: Статика | F8: 5 | G8: CH-03, PR-02, LC-04 | I8: Seedance | J8: Раскадровка | M8: Не начато | N8: Средний
A9: 02.02 | B9: 2 | C9: Правитель Юга зеркально | D9: Средний | E9: Зеркально 2.1 | F9: 5 | G9: CH-04, PR-02, LC-05 | I9: Seedance | J9: Раскадровка | M9: Не начато | N9: Средний
A10: 02.03 | B10: 2 | C10: Слуги закрывают дыры в стене золотой тканью | D10: Средний | E10: Панорама | F10: 4 | G10: CH-09, PR-04, LC-04 | I10: Seedance | J10: Раскадровка | M10: Не начато | N10: Средний
A11: 02.04 | B11: 2 | C11: Слуги натирают рукавами медный купол | D11: Средний | E11: Панорама | F11: 4 | G11: CH-09, LC-05 | I11: Seedance | J11: Раскадровка | M11: Не начато | N11: Средний
A12: 02.05 | B12: 2 | C12: Правитель Севера: реплика | D12: Крупный | E12: Статика | F12: 6 | G12: CH-03, LC-04 | H12: We are poor. But they? Look how they shine! | I12: Seedance | J12: Раскадровка | M12: Не начато | N12: Средний
A13: 02.06 | B13: 2 | C13: Правитель Юга: та же реплика зеркально | D13: Крупный | E13: Зеркально 2.5 | F13: 6 | G13: CH-04, LC-05 | H13: We are poor. But they? Look how they shine! | I13: Seedance | J13: Раскадровка | M13: Не начато | N13: Средний
A14: 03.01 | B14: 3 | C14: Мастерская красильщика у стены, овца у чана | D14: Общий | E14: Статика | F14: 5 | G14: CH-05, AN-01, PR-03, LC-06 | I14: Seedance | J14: Раскадровка | M14: Не начато | N14: Средний
A15: 03.02 | B15: 3 | C15: Красильщик спотыкается, чан с оранжевой краской опрокидывается | D15: Средний | E15: Ручная камера | F15: 4 | G15: CH-05, PR-03, LC-06 | H15: Грохот, плеск | I15: Seedance | J15: Раскадровка | M15: Не начато | N15: Средний
A16: 03.03 | B16: 3 | C16: Овца в саже и жидкой краске выскакивает (видно, что краска водная, капает) | D16: Средний | E16: Следим за овцой | F16: 4 | G16: AN-01, PR-03 | H16: Блеяние | I16: Seedance | J16: Раскадровка | M16: Не начато | N16: Средний
A17: 03.04 | B17: 3 | C17: Овца несётся по ступеням на стену | D17: Средний | E17: Проводка | F17: 4 | G17: AN-01, LC-02 | I17: Seedance | J17: Раскадровка | M17: Не начато | N17: Средний
A18: 03.05 | B18: 3 | C18: Полосатая овца в героической позе на фоне рассвета | D18: Общий | E18: Нижний ракурс, статика | F18: 8 | G18: AN-01, EF-04, LC-02 | H18: Пауза | I18: Seedance | J18: Раскадровка | M18: Не начато | N18: Средний
A19: 04.01 | B19: 4 | C19: Дозорный Юга щурится в кривую трубу | D19: Крупный | E19: Статика | F19: 3 | G19: CH-02, PR-01, LC-03 | I19: Seedance | J19: Раскадровка | M19: Не начато | N19: Средний
A20: 04.02 | B20: 4 | C20: Через трубу: полосатая овца выглядит саблезубым тигром | D20: POV трубы | E20: Искажение линзы | F20: 4 | G20: AN-01, ST-01 | I20: Seedance | J20: Раскадровка | M20: Не начато | N20: Средний
A21: 04.03 | B21: 4 | C21: Дозорный бежит по городу | D21: Общий | E21: Проводка | F21: 6 | G21: CH-02, LC-07 | H21: Ma lord, ma lord! The North has TIGERS! | I21: Seedance | J21: Раскадровка | M21: Не начато | N21: Средний
A22: 04.04 | B22: 4 | C22: На бегу добавляет подробности | D22: Средний | E22: Проводка | F22: 6 | G22: CH-02, LC-07 | H22: Many. Angry. One with a tail. | I22: Seedance | J22: Раскадровка | M22: Не начато | N22: Средний
A23: 04.05 | B23: 4 | C23: Влетает во дворец, падает к ногам правителя Юга | D23: Средний | E23: Статика | F23: 5 | G23: CH-02, CH-04, LC-05 | I23: Seedance | J23: Раскадровка | M23: Не начато | N23: Средний
A24: 04.06 | B24: 4 | C24: Правитель Юга, пауза, реакция | D24: Крупный | E24: Статика | F24: 6 | G24: CH-04, LC-05 | H24: We have no tigers. | I24: Seedance | J24: Раскадровка | M24: Не начато | N24: Средний
A25: 05.01 | B25: 5 | C25: Правитель Юга собирает ремесленников, задача «за ночь» | D25: Общий | E25: Статика | F25: 6 | G25: CH-04, CH-10, LC-08 | I25: Seedance | J25: Раскадровка | M25: Не начато | N25: Средний
A26: 05.02 | B26: 5 | C26: Ночная сборка: три осла в ряд, ковёр, печные трубы-бивни | D26: Средний | E26: Монтажная нарезка | F26: 8 | G26: CH-10, AN-03, PR-05, LC-08 | H26: Стук, ругань | I26: Seedance | J26: Раскадровка | M26: Не начато | N26: Средний
A27: 05.03 | B27: 5 | C27: Утро: «бронированный слон» шагает по набережной | D27: Общий | E27: Сбоку, проводка | F27: 6 | G27: PR-05, AN-03, LC-09 | H27: Тяжёлые шаги | I27: Seedance | J27: Раскадровка | M27: Не начато | N27: Средний
A28: 05.04 | B28: 5 | C28: Деталь: средний осёл не в ногу, слон переступает рывками | D28: Деталь | E28: Низко, по ногам | F28: 5 | G28: AN-03, PR-05 | I28: Seedance | J28: Раскадровка | M28: Не начато | N28: Средний
A29: 05.05 | B29: 5 | C29: Правитель Юга доволен | D29: Крупный | E29: Статика | F29: 5 | G29: CH-04, LC-09 | H29: Terror. But affordable. | I29: Seedance | J29: Раскадровка | M29: Не начато | N29: Средний
A30: 06.01 | B30: 6 | C30: Дозорный Севера в трубу видит «слона» | D30: POV трубы | E30: Искажение линзы | F30: 4 | G30: CH-01, PR-01, PR-05, ST-01 | I30: Seedance | J30: Раскадровка | M30: Не начато | N30: Средний
A31: 06.02 | B31: 6 | C31: Таверна: его угощают, он рассказывает | D31: Средний | E31: Медленный наезд | F31: 8 | G31: CH-01, CH-11, PR-15, LC-10 | H31: A hundred elephants. They breathe fire. | I31: Seedance | J31: Раскадровка | M31: Не начато | N31: Средний
A32: 06.03 | B32: 6 | C32: Слушатели в ужасе несут ещё угощения | D32: Средний | E32: Статика | F32: 4 | G32: CH-11, PR-15, LC-10 | I32: Seedance | J32: Раскадровка | M32: Не начато | N32: Средний
A33: 06.04 | B33: 6 | C33: Правитель Севера отдаёт приказ | D33: Крупный | E33: Статика | F33: 5 | G33: CH-03, LC-04 | H33: A thousand soldiers. By morning. | I33: Seedance | J33: Раскадровка | M33: Не начато | N33: Средний
A34: 06.05 | B34: 6 | C34: Крыши: палки с медными тазами — «золотые щиты» | D34: Общий | E34: Панорама по крышам | F34: 5 | G34: PR-06, LC-11 | I34: Seedance | J34: Раскадровка | M34: Не начато | N34: Средний
A35: 06.06 | B35: 6 | C35: Кузница: сырая солома с перцем, чёрный дым, кузнецы чихают | D35: Средний | E35: Статика | F35: 4 | G35: CH-13, EF-02, LC-12 | H35: Чихание | I35: Seedance | J35: Раскадровка | M35: Не начато | N35: Средний
A36: 07.01 | B36: 7 | C36: Юг: картонные великаны на ходулях | D36: Общий | E36: Динамика | F36: 7 | G36: PR-08, CH-10, LC-03 | H36: Барабаны ↑ | I36: Seedance | J36: Раскадровка | M36: Не начато | N36: Средний
A37: 07.02 | B37: 7 | C37: Север: огромные чучела на подставках (Ньепи) | D37: Общий | E37: Динамика | F37: 7 | G37: PR-09, CH-10, LC-02 | H37: Барабаны ↑ | I37: Seedance | J37: Раскадровка | M37: Не начато | N37: Средний
A38: 07.03 | B38: 7 | C38: Юг: брёвна, раскрашенные под пушки | D38: Средний | E38: Динамика | F38: 6 | G38: PR-10, CH-10 | H38: Барабаны ↑ | I38: Seedance | J38: Раскадровка | M38: Не начато | N38: Средний
A39: 07.04 | B39: 7 | C39: Север: бочки и колёса гремят как колесницы | D39: Средний | E39: Динамика | F39: 6 | G39: PR-11, CH-10 | H39: Грохот, барабаны ↑ | I39: Seedance | J39: Раскадровка | M39: Не начато | N39: Средний
A40: 07.05 | B40: 7 | C40: Юг: стадо овец раскрашивают под тигров; правитель Юга кивает | D40: Средний | E40: Динамика | F40: 7 | G40: AN-02, CH-04, CH-08 | H40: Барабаны ↑ (ввести барабанщика) | I40: Seedance | J40: Раскадровка | M40: Не начато | N40: Средний
...

Sheet Ассеты
A1: ID | B1: Тип | C1: Название | D1: Описание / внешний вид | E1: Состояния и версии (континьюити) | F1: Сцены | G1: Шотов | H1: Референс (ссылка / файл) | I1: Статус | J1: Приоритет | K1: Ответственный | L1: Дедлайн | M1: Комментарий
A2: CH-01 | B2: Персонаж | C2: Дозорный Севера | D2: Полуслепой, корявый, с важным видом. Мерзкая родинка (у кого — решить). | E2: Дозор / таверна (сытый) / финал за столом | F2: 1, 6, 10, 12 | G2: =IF(A2="","",COUNTIF(Шоты!$G$2:$G$500,"*"&A2&"*")) -> 7 | I2: Не начато | J2: Высокий | M2: Имя не выбрано. Родинка: CH-01 или CH-02?
A3: CH-02 | B3: Персонаж | C3: Дозорный Юга | D3: Полуслепой, корявый, с важным видом. Пара к CH-01, но отличим с первого взгляда. | E3: Дозор / бег по городу / финал за столом | F3: 1, 4, 10, 12 | G3: =IF(A3="","",COUNTIF(Шоты!$G$2:$G$500,"*"&A3&"*")) -> 9 | I3: Не начато | J3: Высокий | M3: Голландский акцент — вариант озвучки
A4: CH-03 | B4: Персонаж | C4: Правитель Севера | D4: Дуэт «мелкий и крупный», не копия Астерикса и Обеликса. | E4: Дворец / среди бутафории / флотилия | F4: 2, 6, 7, 9, 11 | G4: =IF(A4="","",COUNTIF(Шоты!$G$2:$G$500,"*"&A4&"*")) -> 8 | I4: Не начато | J4: Высокий | M4: Решить: мелкий или крупный
A5: CH-04 | B5: Персонаж | C5: Правитель Юга | D5: Вторая половина дуэта, контраст силуэта с CH-03. | E5: Дворец / двор / флотилия | F5: 2, 4, 5, 7, 9, 11 | G5: =IF(A5="","",COUNTIF(Шоты!$G$2:$G$500,"*"&A5&"*")) -> 11 | I5: Не начато | J5: Высокий
A6: CH-05 | B6: Персонаж | C6: Красильщик | D6: Неуклюжий ремесленник с руками в краске. | E6: — | F6: 3 | G6: =IF(A6="","",COUNTIF(Шоты!$G$2:$G$500,"*"&A6&"*")) -> 2 | I6: Не начато | J6: Средний
A7: CH-06 | B7: Персонаж | C7: Глашатай | D7: Есть в списке персонажей сценария. | E7: — | F7: — | G7: =IF(A7="","",COUNTIF(Шоты!$G$2:$G$500,"*"&A7&"*")) -> 0 | I7: Не начато | J7: Средний | M7: В сценах не задействован: дать роль (напр. объявляет приказ в 6) или вырезать
A8: CH-07 | B8: Массовка | C8: Мальчишки-бегуны | D8: Группа 3–4 мальчишек. | E8: — | F8: 8 | G8: =IF(A8="","",COUNTIF(Шоты!$G$2:$G$500,"*"&A8&"*")) -> 1 | I8: Не начато | J8: Средний
A9: CH-08 | B9: Персонаж | C9: Мальчишка-барабанщик | D9: Важен для финала: его смех ломает тишину. | E9: Бодро / медленно / смеётся | F9: 7, 8, 11 | G9: =IF(A9="","",COUNTIF(Шоты!$G$2:$G$500,"*"&A9&"*")) -> 3 | I9: Не начато | J9: Средний | M9: Показать раньше 11, иначе его смех не сработает
A10: CH-09 | B10: Массовка | C10: Слуги правителей | F10: 2 | G10: =IF(A10="","",COUNTIF(Шоты!$G$2:$G$500,"*"&A10&"*")) -> 2 | I10: Не начато | J10: Средний
A11: CH-10 | B11: Массовка | C11: Ремесленники | D11: Безымянная толпа, строят бутафорию, работают в азарте. | F11: 5, 7 | G11: =IF(A11="","",COUNTIF(Шоты!$G$2:$G$500,"*"&A11&"*")) -> 6 | I11: Не начато | J11: Средний
A12: CH-11 | B12: Массовка | C12: Жители / слушатели в таверне | E12: Смеются днём / боятся вечером | F12: 6, 8, 11 | G12: =IF(A12="","",COUNTIF(Шоты!$G$2:$G$500,"*"&A12&"*")) -> 5 | I12: Не начато | J12: Средний
A13: CH-12 | B13: Массовка | C13: Старики и мальчишки на лодках | D13: Держат тазы, зажимают морду овце. | F13: 10, 11 | G13: =IF(A13="","",COUNTIF(Шоты!$G$2:$G$500,"*"&A13&"*")) -> 3 | I13: Не начато | J13: Средний
A14: CH-13 | B14: Массовка | C14: Кузнецы | F14: 6 | G14: =IF(A14="","",COUNTIF(Шоты!$G$2:$G$500,"*"&A14&"*")) -> 1 | I14: Не начато | J14: Средний
A15: AN-01 | B15: Животное | C15: Овца-«тигр» | D15: Главная овца фильма. | E15: 1) белая 2) в саже и краске 3) в оранжево-чёрных полосах 4) мокрая, краска смыта | F15: 3, 4, 11 | G15: =IF(A15="","",COUNTIF(Шоты!$G$2:$G$500,"*"&A15&"*")) -> 6 | I15: Не начато | J15: Высокий | M15: Чья овца смывается в 11: северная (сц. 3) или из южного стада (сц. 7)? См. «Сетапы»
A16: AN-02 | B16: Животное | C16: Стадо овец под тигров (Юг) | E16: Белые / раскрашенные / на кораблях | F16: 7, 8, 10 | G16: =IF(A16="","",COUNTIF(Шоты!$G$2:$G$500,"*"&A16&"*")) -> 4 | I16: Не начато | J16: Средний
A17: AN-03 | B17: Животное | C17: Три осла «слона» (Юг) | D17: Средний идёт не в ногу. | E17: Под ковром / морда наружу, жуёт | F17: 5, 11 | G17: =IF(A17="","",COUNTIF(Шоты!$G$2:$G$500,"*"&A17&"*")) -> 4 | I17: Не начато | J17: Средний
A18: AN-04 | B18: Животное | C18: Ослы в доспехах из кастрюль (Север) | F18: 7 | G18: =IF(A18="","",COUNTIF(Шоты!$G$2:$G$500,"*"&A18&"*")) -> 1 | I18: Не начато | J18: Средний
A19: PR-01 | B19: Реквизит | C19: Кривая медная подзорная труба | D19: Огромная, медная, главный артефакт фильма. | E19: Одинаковые у обоих дозорных или разные — решить | F19: 1, 4, 6, 8, 10, 12 | G19: =IF(A19="","",COUNTIF(Шоты!$G$2:$G$500,"*"&A19&"*")) -> 7 | I19: Не начато | J19: Высокий | M19: Ключевой ассет: делать референс первым
A20: PR-02 | B20: Реквизит | C20: Трубы правителей | D20: Богаче дозорных, такие же кривые. | F20: 2 | G20: =IF(A20="","",COUNTIF(Шоты!$G$2:$G$500,"*"&A20&"*")) -> 2 | I20: Не начато | J20: Средний
A21: PR-03 | B21: Реквизит | C21: Чан с оранжевой водной краской | E21: Полный / опрокинут | F21: 3 | G21: =IF(A21="","",COUNTIF(Шоты!$G$2:$G$500,"*"&A21&"*")) -> 3 | I21: Не начато | J21: Средний
A22: PR-04 | B22: Реквизит | C22: Золотая ткань | D22: Прикрывает дыры в стенах. | F22: 2 | G22: =IF(A22="","",COUNTIF(Шоты!$G$2:$G$500,"*"&A22&"*")) -> 1 | I22: Не начато | J22: Средний
A23: PR-05 | B23: Бутафория | C23: «Бронированный слон» | D23: Три осла, огромный ковёр, печные трубы как бивни, хобот из печной трубы. | E23: Сборка / собран, на ходу / на палубе / хобот отвалился | F23: 5, 6, 9, 10, 11 | G23: =IF(A23="","",COUNTIF(Шоты!$G$2:$G$500,"*"&A23&"*")) -> 7 | I23: Не начато | J23: Высокий | M23: Самый сложный ассет: тест Seedance в первую очередь
A24: PR-06 | B24: Реквизит | C24: Медные тазы — «золотые щиты» | D24: Бабушкины тазы на палках. | E24: На крышах / в руках на лодках / летят в воду | F24: 6, 10, 11, 12 | G24: =IF(A24="","",COUNTIF(Шоты!$G$2:$G$500,"*"&A24&"*")) -> 5 | I24: Не начато | J24: Средний
A25: PR-08 | B25: Бутафория | C25: Картонные великаны на ходулях (Юг) | E25: Вблизи картон / через трубу живые | F25: 7, 8, 9 | G25: =IF(A25="","",COUNTIF(Шоты!$G$2:$G$500,"*"&A25&"*")) -> 3 | I25: Не начато | J25: Средний
A26: PR-09 | B26: Бутафория | C26: Чучела на подставках (Север) | D26: Образец: балийский Ньепи (огох-огох). | E26: На берегу / на носах кораблей | F26: 7, 9, 10 | G26: =IF(A26="","",COUNTIF(Шоты!$G$2:$G$500,"*"&A26&"*")) -> 3 | I26: Не начато | J26: Средний
A27: PR-10 | B27: Бутафория | C27: Брёвна-пушки (Юг) | D27: Брёвна, раскрашенные под пушки. | F27: 7 | G27: =IF(A27="","",COUNTIF(Шоты!$G$2:$G$500,"*"&A27&"*")) -> 1 | I27: Не начато | J27: Средний
A28: PR-11 | B28: Бутафория | C28: Бочки и колёса-«колесницы» (Север) | D28: Гремят как колесницы. | F28: 7 | G28: =IF(A28="","",COUNTIF(Шоты!$G$2:$G$500,"*"&A28&"*")) -> 1 | I28: Не начато | J28: Средний
A29: PR-12 | B29: Бутафория | C29: Доспехи из кастрюль | D29: На ослах Севера. | F29: 7, 9 | G29: =IF(A29="","",COUNTIF(Шоты!$G$2:$G$500,"*"&A29&"*")) -> 2 | I29: Не начато | J29: Средний
A30: PR-13 | B30: Реквизит | C30: Картонные и деревянные мечи | E30: Целый / гнётся | F30: 8, 11 | G30: =IF(A30="","",COUNTIF(Шоты!$G$2:$G$500,"*"&A30&"*")) -> 2 | I30: Не начато | J30: Средний
A31: PR-14 | B31: Реквизит | C31: Барабан | F31: 7, 8, 11 | G31: =IF(A31="","",COUNTIF(Шоты!$G$2:$G$500,"*"&A31&"*")) -> 2 | I31: Не начато | J31: Средний
A32: PR-15 | B32: Реквизит | C32: Еда: угощения, лепёшки, фрукты, кувшины | E32: Таверна / финальный стол | F32: 6, 12 | G32: =IF(A32="","",COUNTIF(Шоты!$G$2:$G$500,"*"&A32&"*")) -> 4 | I32: Не начато | J32: Средний
A33: PR-16 | B33: Реквизит | C33: Сохнущее бельё, заплатки | D33: Сет-дрессинг бедности. | F33: 1 | G33: =IF(A33="","",COUNTIF(Шоты!$G$2:$G$500,"*"&A33&"*")) -> 1 | I33: Не начато | J33: Средний
A34: LC-01 | B34: Локация | C34: Пролив между островами | E34: День / туман ночью / рассвет | F34: 1, 10, 11, 12 | G34: =IF(A34="","",COUNTIF(Шоты!$G$2:$G$500,"*"&A34&"*")) -> 4 | I34: Не начато | J34: Средний
A35: LC-02 | B35: Локация | C35: Северный остров, стена-крепость | E35: Через трубу богатый / без трубы бедный | F35: 1, 3, 7, 8 | G35: =IF(A35="","",COUNTIF(Шоты!$G$2:$G$500,"*"&A35&"*")) -> 8 | I35: Не начато | J35: Средний | M35: Палитра Севера — в ST-01
A36: LC-03 | B36: Локация | C36: Южный остров, стена-крепость | E36: Через трубу богатый / без трубы бедный | F36: 1, 4, 7, 8 | G36: =IF(A36="","",COUNTIF(Шоты!$G$2:$G$500,"*"&A36&"*")) -> 5 | I36: Не начато | J36: Средний | M36: Палитра Юга — в ST-01
A37: LC-04 | B37: Локация | C37: Дворец Севера | F37: 2, 6, 9 | G37: =IF(A37="","",COUNTIF(Шоты!$G$2:$G$500,"*"&A37&"*")) -> 5 | I37: Не начато | J37: Средний
A38: LC-05 | B38: Локация | C38: Дворец Юга (медный купол) | F38: 2, 4, 9 | G38: =IF(A38="","",COUNTIF(Шоты!$G$2:$G$500,"*"&A38&"*")) -> 6 | I38: Не начато | J38: Средний
A39: LC-06 | B39: Локация | C39: Мастерская красильщика (Север) | D39: У стены. | F39: 3 | G39: =IF(A39="","",COUNTIF(Шоты!$G$2:$G$500,"*"&A39&"*")) -> 2 | I39: Не начато | J39: Средний
A40: LC-07 | B40: Локация | C40: Улицы Юга | D40: Маршрут бегущего дозорного. | F40: 4 | G40: =IF(A40="","",COUNTIF(Шоты!$G$2:$G$500,"*"&A40&"*")) -> 2 | I40: Не начато | J40: Средний
...

Sheet Сетапы
A1: № | B1: Мотив / сетап | C1: Сетап (шот) | D1: Пэйофф (шот) | E1: Что должен считать зритель | F1: Риск / открытый вопрос | G1: Статус | H1: Комментарий
A2: 1 | B2: Кривая труба врёт | C2: 01.04, 01.05 | D2: 11.03–11.05, 12.04 | E2: Через трубу богато и страшно, вблизи бедно и смешно | F2: POV-кадры должны быть узнаваемы одним луком (ST-01) | G2: Не начато
A3: 2 | B3: Третий остров | C3: 01.06 | D3: 12.04 | E3: Силуэт был с самого начала, его никто не заметил | F3: Заметен при пересмотре, но не бросается в глаза в первый раз | G3: Не начато
A4: 3 | B4: Водная краска на овце | C4: 03.03 | D4: 11.04 | E4: Краска смывается, потому что она водная | F4: Показать в 3.03, что краска жидкая и капает. Чья овца смывается в 11: северная из сц. 3 или из южного стада? | G4: Не начато
A5: 4 | B5: «Ma lord, ma lord!» | C5: 04.03 | D5: 12.05 | E5: Реплика-рефрен, в финале звучит вопросом | F5: Одинаковая интонация и голос дозорного | G5: Не начато
A6: 5 | B6: Накидывание подробностей | C6: 04.04 | D6: 06.02 | E6: С каждым пересказом чудище страшнее | F6: В сценарии только 2 пересказа, а мотив обещает рост «с каждой сценой». Добавить третий (напр. бегуны в 8.04)? | G6: Не начато
A7: 6 | B7: Барабан нарастает | C7: 07.01–07.06 | D7: 11.06 | E7: Тишина бьёт сильнее любого звука | F7: Барабанщик впервые в кадре только в 7.05: показать его раньше | G7: Не начато
A8: 7 | B8: Хобот из печной трубы | C8: 05.02 | D8: 11.03 | E8: Слон — это ослы и печные трубы | F8: Хобот должен быть заметен как отдельная деталь в сборке | G8: Не начато
A9: 8 | B9: Средний осёл не в ногу | C9: 05.04 | D9: 11.03 | E9: Жующая морда — тот самый осёл | F9: Один и тот же осёл (AN-03) в обоих шотах | G9: Не начато
A10: 9 | B10: Медные тазы = золотые щиты | C10: 06.05 | D10: 10.04, 11.05, 12.01 | E10: «Золотое войско» — это бабушкины тазы | G10: Не начато
A11: 10 | B11: Туман | C11: 09.03 | D11: 10.01–11.02 | E11: План правителей сработал на обоих, и поэтому провалился | G11: Не начато
A12: 11 | B12: «Мы бедные, а они сияют» | C12: 02.05, 02.06 | D12: 11.06 | E12: Оба наконец видят, что бедны одинаково | G12: Не начато
A13: 12 | B13: Зеркальная симметрия | C13: 01.01 | D13: 11.01 | E13: Нос в нос — финальное зеркало | F13: Повторить композицию 1.1 | G13: Не начато
A14: 13 | B14: Дозорных угощают | C14: 06.02, 06.03 | D14: 12.03 | E14: Дозорные снова жуют: всё по кругу | G14: Не начато

Sheet Звук
A1: ID | B1: Сцена | C1: Шот | D1: Тип | E1: Кто / источник | F1: Текст EN (= субтитр) | G1: Перевод RU | H1: Озвучка / права | I1: Статус | J1: Комментарий
A2: SND-01 | B2: 1 | C2: 01.01 | D2: Атмосфера | E2: Ветер, чайки, скрип труб | I2: Не начато
A3: SND-02 | B3: 2 | C3: 02.05 | D3: Реплика | E3: Правитель Севера | F3: We are poor. But they? Look how they shine! | G3: Мы-то бедные. А они? Смотри, как сияют! | I3: Не начато
A4: SND-03 | B4: 2 | C4: 02.06 | D4: Реплика | E4: Правитель Юга | F4: We are poor. But they? Look how they shine! | G4: Мы-то бедные. А они? Смотри, как сияют! | I4: Не начато
A5: SND-04 | B5: 3 | C5: 03.03 | D5: SFX | E5: Овца | G5: Блеяние | I5: Не начато
A6: SND-05 | B6: 4 | C6: 04.03 | D6: Реплика | E6: Дозорный Юга | F6: Ma lord, ma lord! The North has TIGERS! | G6: Милорд, милорд! У Севера ТИГРЫ! | I6: Не начато
A7: SND-06 | B7: 4 | C7: 04.04 | D7: Реплика | E7: Дозорный Юга | F7: Many. Angry. One with a tail. | G7: Много. Злые. Один с хвостом. | I7: Не начато
A8: SND-07 | B8: 4 | C8: 04.06 | D8: Реплика | E8: Правитель Юга | F8: We have no tigers. | G8: У нас нет тигров. | I8: Не начато
A9: SND-08 | B9: 5 | C9: 05.03 | D9: SFX | E9: Слон из ослов | G9: Тяжёлые неровные шаги | I9: Не начато
A10: SND-09 | B10: 5 | C10: 05.05 | D10: Реплика | E10: Правитель Юга | F10: Terror. But affordable. | G10: Ужас. Но недорого. | I10: Не начато
A11: SND-10 | B11: 6 | C11: 06.02 | D11: Реплика | E11: Дозорный Севера | F11: A hundred elephants. They breathe fire. | G11: Сто слонов. Дышат огнём. | I11: Не начато
A12: SND-11 | B12: 6 | C12: 06.04 | D12: Реплика | E12: Правитель Севера | F12: A thousand soldiers. By morning. | G12: Тысячу солдат. К утру. | I12: Не начато
A13: SND-12 | B13: 6 | C13: 06.06 | D13: SFX | E13: Кузнецы | G13: Чихание от перечного дыма | I13: Не начато
A14: SND-13 | B14: 7 | C14: 07.01 | D14: Музыка | E14: Барабанная партия | G14: Нарастает через сц. 7–11 | I14: Не начато
A15: SND-14 | B15: 8 | C15: 08.04 | D15: Реплика | E15: Мальчишки-бегуны | F15: Attack at dawn! | G15: Штурм на рассвете! | I15: Не начато
A16: SND-15 | B16: 9 | C16: 09.04 | D16: Реплика | E16: Правитель Севера | F16: In the fog, a donkey is a dragon. | G16: В тумане осёл как дракон. | I16: Не начато
A17: SND-16 | B17: 9 | C17: 09.05 | D17: Реплика | E17: Правитель Юга | F17: In the fog, a donkey is a dragon. | G17: В тумане осёл как дракон. | I17: Не начато
A18: SND-17 | B18: 10 | C18: 10.05 | D18: SFX | E18: Овца | G18: Блеяние, зажатое рукой | I18: Не начато
A19: SND-18 | B19: 11 | C19: 11.01 | D19: SFX | E19: Корабли | G19: Глухой удар бортов | I19: Не начато
A20: SND-19 | B20: 11 | C20: 11.06 | D20: Тишина | E20: Все | G20: 10 секунд, барабан молчит | I20: Не начато
A21: SND-20 | B21: 11 | C21: 11.07 | D21: SFX | E21: Барабанщик | G21: Смех, по цепочке | I21: Не начато
A22: SND-21 | B22: 12 | C22: 12.01 | D22: SFX | E22: Лодки | G22: Смех, всплески щитов | I22: Не начато
A23: SND-22 | B23: 12 | C23: 12.05 | D23: Реплика | E23: Оба дозорных | F23: Ma lord?! | G23: Милорд?! | I23: Не начато
A24: SND-23 | B24: 12 | C24: 12.05 | D24: Музыка | E24: Финальные титры | G24: Тема на титры | I24: Не начато

Sheet Задачи
A1: ID | B1: Блок | C1: Задача | D1: Ответственный | E1: Дедлайн | F1: Дней осталось | G1: Статус | H1: Приоритет | I1: Комментарий
A2: T-01 | B2: Конкурс | C2: Сценарная разбивка v2 (12 сцен, 6 мин) | E2: 46324 | F2: =IF(OR(E2="",G2="Готово",G2="Вырезано"),"",E2-TODAY()) | G2: Готово | H2: Высокий | I2: Пример заполненной строки
A3: T-02 | B3: Конкурс | C3: Выбрать тему из пяти обязательных | E3: 46326 | F3: =IF(OR(E3="",G3="Готово",G3="Вырезано"),"",E3-TODAY()) -> 1 | G3: Не начато | H3: Высокий | I3: Напрашивается «Truth, Fake News & Misinformation»: фильм целиком про искажённую картинку и слухи
A4: T-03 | B4: Конкурс | C4: Перечитать официальные правила на 1billionsummit.com | E4: 46326 | F4: =IF(OR(E4="",G4="Готово",G4="Вырезано"),"",E4-TODAY()) -> 1 | G4: Не начато | H4: Высокий | I4: 5–7 мин, 16:9 1080p, MOV/MP4, ≥70% Seedance, англ. субтитры
A5: T-04 | B5: Конкурс | C5: Скачать интро-карточку организатора | E5: 46327 | F5: =IF(OR(E5="",G5="Готово",G5="Вырезано"),"",E5-TODAY()) -> 2 | G5: Не начато | H5: Средний | I5: Ставится перед фильмом
A6: T-05 | B6: Препродакшн | C6: Имена персонажей вместо ролей | E6: 46327 | F6: =IF(OR(E6="",G6="Готово",G6="Вырезано"),"",E6-TODAY()) -> 2 | G6: Не начато | H6: Средний
A7: T-06 | B7: Препродакшн | C7: Решить, кто из правителей мелкий, кто крупный | E7: 46327 | F7: =IF(OR(E7="",G7="Готово",G7="Вырезано"),"",E7-TODAY()) -> 2 | G7: Не начато | H7: Высокий
A8: T-07 | B8: Препродакшн | C8: Решить, у какого дозорного родинка | E8: 46327 | F8: =IF(OR(E8="",G8="Готово",G8="Вырезано"),"",E8-TODAY()) -> 2 | G8: Не начато | H8: Низкий
A9: T-08 | B9: Препродакшн | C9: Закрыть открытые вопросы с листа «Сетапы» | E9: 46328 | F9: =IF(OR(E9="",G9="Готово",G9="Вырезано"),"",E9-TODAY()) -> 3 | G9: Не начато | H9: Высокий | I9: Чья овца смывается, третий пересказ, ранний показ барабанщика, глашатай
A10: T-09 | B10: Препродакшн | C10: Лук-бук: палитры Севера и Юга, лук «через трубу» (ST-01) | E10: 46328 | F10: =IF(OR(E10="",G10="Готово",G10="Вырезано"),"",E10-TODAY()) -> 3 | G10: Не начато | H10: Высокий
A11: T-10 | B11: Препродакшн | C11: Character sheets: 2 дозорных, 2 правителя | E11: 46329 | F11: =IF(OR(E11="",G11="Готово",G11="Вырезано"),"",E11-TODAY()) -> 4 | G11: Не начато | H11: Высокий | I11: Консистентность героев — главный риск AI-фильма
A12: T-11 | B12: Препродакшн | C12: Референсы ключевых ассетов: труба, овца (4 состояния), слон | E12: 46330 | F12: =IF(OR(E12="",G12="Готово",G12="Вырезано"),"",E12-TODAY()) -> 5 | G12: Не начато | H12: Высокий
A13: T-12 | B13: Препродакшн | C13: Блокауты сложных шотов: 05.03, 10.02, 10.03, 11.01, 11.03, 11.04 | E13: 46331 | F13: =IF(OR(E13="",G13="Готово",G13="Вырезано"),"",E13-TODAY()) -> 6 | G13: Не начато | H13: Средний
A14: T-13 | B14: Препродакшн | C14: Тест Seedance на три самых сложных шота | E14: 46331 | F14: =IF(OR(E14="",G14="Готово",G14="Вырезано"),"",E14-TODAY()) -> 6 | G14: Не начато | H14: Высокий | I14: Слон в движении, смыв краски, флотилии в тумане
A15: T-14 | B15: Генерация | C15: Сцены 1–4 | E15: 46334 | F15: =IF(OR(E15="",G15="Готово",G15="Вырезано"),"",E15-TODAY()) -> 9 | G15: Не начато | H15: Высокий
A16: T-15 | B16: Генерация | C16: Сцены 5–8 | E16: 46337 | F16: =IF(OR(E16="",G16="Готово",G16="Вырезано"),"",E16-TODAY()) -> 12 | G16: Не начато | H16: Высокий
A17: T-16 | B17: Генерация | C17: Сцены 9–12 | E17: 46340 | F17: =IF(OR(E17="",G17="Готово",G17="Вырезано"),"",E17-TODAY()) -> 15 | G17: Не начато | H17: Высокий
A18: T-17 | B18: Звук | C18: Озвучка реплик (голландский акцент — проверить права на голос) | E18: 46340 | F18: =IF(OR(E18="",G18="Готово",G18="Вырезано"),"",E18-TODAY()) -> 15 | G18: Не начато | H18: Средний
A19: T-18 | B19: Монтаж | C19: Черновой монтаж (assembly) | E19: 46341 | F19: =IF(OR(E19="",G19="Готово",G19="Вырезано"),"",E19-TODAY()) -> 16 | G19: Не начато | H19: Высокий
A20: T-19 | B20: Звук | C20: Барабанная партия и музыка: свои или с лицензией | E20: 46341 | F20: =IF(OR(E20="",G20="Готово",G20="Вырезано"),"",E20-TODAY()) -> 16 | G20: Не начато | H20: Средний
A21: T-20 | B21: Звук | C21: SFX и атмосферы (лист «Звук») | E21: 46342 | F21: =IF(OR(E21="",G21="Готово",G21="Вырезано"),"",E21-TODAY()) -> 17 | G21: Не начато | H21: Средний
A22: T-21 | B22: Монтаж | C22: Цветокоррекция и грейд | E22: 46342 | F22: =IF(OR(E22="",G22="Готово",G22="Вырезано"),"",E22-TODAY()) -> 17 | G22: Не начато | H22: Средний
A23: T-22 | B23: Монтаж | C23: Английские субтитры | E23: 46343 | F23: =IF(OR(E23="",G23="Готово",G23="Вырезано"),"",E23-TODAY()) -> 18 | G23: Не начато | H23: Высокий | I23: Обязательны, ссылка должна играть фильм с ними
A24: T-23 | B24: Монтаж | C24: Проверить хронометраж: строго 5:00–7:00 с запасом | E24: 46343 | F24: =IF(OR(E24="",G24="Готово",G24="Вырезано"),"",E24-TODAY()) -> 18 | G24: Не начато | H24: Высокий | I24: Неясно, входит ли интро-карточка — держим запас
A25: T-24 | B25: Монтаж | C25: Проверить долю Seedance ≥70% по листу «Шоты» | E25: 46343 | F25: =IF(OR(E25="",G25="Готово",G25="Вырезано"),"",E25-TODAY()) -> 18 | G25: Не начато | H25: Высокий | I25: Цифра на Дашборде
A26: T-25 | B26: Сдача | C26: Экспорт 16:9 1080p MOV/MP4 с интро-карточкой | E26: 46343 | F26: =IF(OR(E26="",G26="Готово",G26="Вырезано"),"",E26-TODAY()) -> 18 | G26: Не начато | H26: Высокий
A27: T-26 | B27: Сдача | C27: Залить как приватную / unlisted ссылку и проверить воспроизведение | E27: 46344 | F27: =IF(OR(E27="",G27="Готово",G27="Вырезано"),"",E27-TODAY()) -> 19 | G27: Не начато | H27: Высокий | I27: Не публичную
A28: T-27 | B28: Сдача | C28: Заполнить форму: автор, фильм, как сделан и какими AI-инструментами, проверка | E28: 46344 | F28: =IF(OR(E28="",G28="Готово",G28="Вырезано"),"",E28-TODAY()) -> 19 | G28: Не начато | H28: Высокий | I28: Описание пайплайна берём из листа «Шоты»
A29: T-28 | B29: Сдача | C29: ПОДАТЬ ЗАЯВКУ | E29: 46344 | F29: =IF(OR(E29="",G29="Готово",G29="Вырезано"),"",E29-TODAY()) -> 19 | G29: Не начато | H29: Высокий | I29: Официальный дедлайн 20.11, по Дубаю (UTC+4) = 22:59 по Москве
A30: T-29 | B30: Сдача | C30: Нарезать 4-минутную версию для других конкурсов (опционально) | E30: 46356 | F30: =IF(OR(E30="",G30="Готово",G30="Вырезано"),"",E30-TODAY()) -> 31 | G30: Не начато | H30: Низкий | I30: Схема склеек — колонка «Если сокращать» на листе «Сцены»
F31: =IF(OR(E31="",G31="Готово",G31="Вырезано"),"",E31-TODAY())
F32: =IF(OR(E32="",G32="Готово",G32="Вырезано"),"",E32-TODAY())
F33: =IF(OR(E33="",G33="Готово",G33="Вырезано"),"",E33-TODAY())
F34: =IF(OR(E34="",G34="Готово",G34="Вырезано"),"",E34-TODAY())
F35: =IF(OR(E35="",G35="Готово",G35="Вырезано"),"",E35-TODAY())
F36: =IF(OR(E36="",G36="Готово",G36="Вырезано"),"",E36-TODAY())
F37: =IF(OR(E37="",G37="Готово",G37="Вырезано"),"",E37-TODAY())
F38: =IF(OR(E38="",G38="Готово",G38="Вырезано"),"",E38-TODAY())
F39: =IF(OR(E39="",G39="Готово",G39="Вырезано"),"",E39-TODAY())
F40: =IF(OR(E40="",G40="Готово",G40="Вырезано"),"",E40-TODAY())
...

Sheet Справочник
A1: Статус | B1: Приоритет | C1: Тип ассета | D1: Инструмент | E1: Этап шота | F1: Крупность | G1: Блок задач | H1: Тип звука
A2: Не начато | B2: Высокий | C2: Персонаж | D2: Seedance | E2: Раскадровка | F2: Общий | G2: Конкурс | H2: Реплика
A3: В работе | B3: Средний | C3: Массовка | D3: Другая AI-видео | E3: Блокаут | F3: Средний | G3: Препродакшн | H3: SFX
A4: На проверке | B4: Низкий | C4: Животное | D4: AI-картинка (стоп-кадр) | E4: Промпт | F4: Крупный | G4: Генерация | H4: Музыка
A5: Доработать | C5: Реквизит | D5: Blender / 3D | E5: Генерация | F5: Деталь | G5: Монтаж | H5: Тишина
A6: Готово | C6: Бутафория | D6: Графика / титры | E6: Отбор дубля | F6: POV трубы | G6: Звук | H6: Атмосфера
A7: Вырезано | C7: Локация | D7: Live action | E7: В монтаже | F7: Сплит / зеркало | G7: Сдача
C8: Корабль | E8: Финал
C9: Эффект / среда
C10: Стиль / лук
A12: Чтобы добавить вариант в список, впишите его в конец колонки и расширьте диапазон в Данные → Проверка данных.
